[2025-10-31T09:58:44.049+0000] {local_task_job_runner.py:123} INFO - ::group::Pre task execution logs
[2025-10-31T09:58:44.070+0000] {taskinstance.py:2612} INFO - Dependencies all met for dep_context=non-requeueable deps ti=<TaskInstance: refresh_bike_db.flask_bike scheduled__2025-10-31T09:57:00+00:00 [queued]>
[2025-10-31T09:58:44.081+0000] {taskinstance.py:2612} INFO - Dependencies all met for dep_context=requeueable deps ti=<TaskInstance: refresh_bike_db.flask_bike scheduled__2025-10-31T09:57:00+00:00 [queued]>
[2025-10-31T09:58:44.084+0000] {taskinstance.py:2865} INFO - Starting attempt 2 of 2
[2025-10-31T09:58:44.100+0000] {taskinstance.py:2888} INFO - Executing <Task(BashOperator): flask_bike> on 2025-10-31 09:57:00+00:00
[2025-10-31T09:58:44.110+0000] {standard_task_runner.py:104} INFO - Running: ['***', 'tasks', 'run', 'refresh_bike_db', 'flask_bike', 'scheduled__2025-10-31T09:57:00+00:00', '--job-id', '367', '--raw', '--subdir', 'DAGS_FOLDER/refresh_bike_db.py', '--cfg-path', '/tmp/tmpmn1ixyhe']
[2025-10-31T09:58:44.112+0000] {standard_task_runner.py:105} INFO - Job 367: Subtask flask_bike
[2025-10-31T09:58:44.113+0000] {logging_mixin.py:190} WARNING - /home/***/.local/lib/python3.12/site-packages/***/task/task_runner/standard_task_runner.py:70 DeprecationWarning: This process (pid=475) is multi-threaded, use of fork() may lead to deadlocks in the child.
[2025-10-31T09:58:44.114+0000] {standard_task_runner.py:72} INFO - Started process 476 to run task
[2025-10-31T09:58:44.178+0000] {task_command.py:467} INFO - Running <TaskInstance: refresh_bike_db.flask_bike scheduled__2025-10-31T09:57:00+00:00 [running]> on host f4cf752b4d1e
[2025-10-31T09:58:44.283+0000] {taskinstance.py:3131} INFO - Exporting env vars: AIRFLOW_CTX_DAG_OWNER='***' AIRFLOW_CTX_DAG_ID='refresh_bike_db' AIRFLOW_CTX_TASK_ID='flask_bike' AIRFLOW_CTX_EXECUTION_DATE='2025-10-31T09:57:00+00:00' AIRFLOW_CTX_TRY_NUMBER='2' AIRFLOW_CTX_DAG_RUN_ID='scheduled__2025-10-31T09:57:00+00:00'
[2025-10-31T09:58:44.285+0000] {taskinstance.py:731} INFO - ::endgroup::
[2025-10-31T09:58:44.303+0000] {subprocess.py:63} INFO - Tmp dir root location: /tmp
[2025-10-31T09:58:44.306+0000] {subprocess.py:75} INFO - Running command: ['/usr/bin/bash', '-c', '\n          set -euxo pipefail\n          cd "$AIRFLOW_HOME/plugins"\n          python app_flask.py\n        ']
[2025-10-31T09:58:44.318+0000] {subprocess.py:86} INFO - Output:
[2025-10-31T09:58:44.320+0000] {subprocess.py:93} INFO - + cd /opt/***/plugins
[2025-10-31T09:58:44.320+0000] {subprocess.py:93} INFO - + python app_flask.py
[2025-10-31T09:58:45.948+0000] {subprocess.py:93} INFO -  * Serving Flask app 'app_flask'
[2025-10-31T09:58:45.949+0000] {subprocess.py:93} INFO -  * Debug mode: on
[2025-10-31T09:58:45.955+0000] {subprocess.py:93} INFO - Address already in use
[2025-10-31T09:58:45.956+0000] {subprocess.py:93} INFO - Port 5000 is in use by another program. Either identify and stop that program, or start the server with a different port.
[2025-10-31T09:58:46.115+0000] {subprocess.py:97} INFO - Command exited with return code 1
[2025-10-31T09:58:46.132+0000] {taskinstance.py:3310} ERROR - Task failed with exception
Traceback (most recent call last):
  File "/home/airflow/.local/lib/python3.12/site-packages/airflow/models/taskinstance.py", line 767, in _execute_task
    result = _execute_callable(context=context, **execute_callable_kwargs)
             ^^^^^^^^^^^^^^^^^^^^^^^^^^^^^^^^^^^^^^^^^^^^^^^^^^^^^^^^^^^^^
  File "/home/airflow/.local/lib/python3.12/site-packages/airflow/models/taskinstance.py", line 733, in _execute_callable
    return ExecutionCallableRunner(
           ^^^^^^^^^^^^^^^^^^^^^^^^
  File "/home/airflow/.local/lib/python3.12/site-packages/airflow/utils/operator_helpers.py", line 252, in run
    return self.func(*args, **kwargs)
           ^^^^^^^^^^^^^^^^^^^^^^^^^^
  File "/home/airflow/.local/lib/python3.12/site-packages/airflow/models/baseoperator.py", line 406, in wrapper
    return func(self, *args, **kwargs)
           ^^^^^^^^^^^^^^^^^^^^^^^^^^^
  File "/home/airflow/.local/lib/python3.12/site-packages/airflow/operators/bash.py", line 249, in execute
    raise AirflowException(
airflow.exceptions.AirflowException: Bash command failed. The command returned a non-zero exit code 1.
[2025-10-31T09:58:46.138+0000] {taskinstance.py:1225} INFO - Marking task as FAILED. dag_id=refresh_bike_db, task_id=flask_bike, run_id=scheduled__2025-10-31T09:57:00+00:00, execution_date=20251031T095700, start_date=20251031T095844, end_date=20251031T095846
[2025-10-31T09:58:46.157+0000] {taskinstance.py:340} INFO - ::group::Post task execution logs
[2025-10-31T09:58:46.159+0000] {standard_task_runner.py:124} ERROR - Failed to execute job 367 for task flask_bike (Bash command failed. The command returned a non-zero exit code 1.; 476)
Traceback (most recent call last):
  File "/home/airflow/.local/lib/python3.12/site-packages/airflow/task/task_runner/standard_task_runner.py", line 117, in _start_by_fork
    ret = args.func(args, dag=self.dag)
          ^^^^^^^^^^^^^^^^^^^^^^^^^^^^^
  File "/home/airflow/.local/lib/python3.12/site-packages/airflow/cli/cli_config.py", line 49, in command
    return func(*args, **kwargs)
           ^^^^^^^^^^^^^^^^^^^^^
  File "/home/airflow/.local/lib/python3.12/site-packages/airflow/utils/cli.py", line 115, in wrapper
    return f(*args, **kwargs)
           ^^^^^^^^^^^^^^^^^^
  File "/home/airflow/.local/lib/python3.12/site-packages/airflow/cli/commands/task_command.py", line 483, in task_run
    task_return_code = _run_task_by_selected_method(args, _dag, ti)
                       ^^^^^^^^^^^^^^^^^^^^^^^^^^^^^^^^^^^^^^^^^^^^
  File "/home/airflow/.local/lib/python3.12/site-packages/airflow/cli/commands/task_command.py", line 256, in _run_task_by_selected_method
    return _run_raw_task(args, ti)
           ^^^^^^^^^^^^^^^^^^^^^^^
  File "/home/airflow/.local/lib/python3.12/site-packages/airflow/cli/commands/task_command.py", line 341, in _run_raw_task
    return ti._run_raw_task(
           ^^^^^^^^^^^^^^^^^
  File "/home/airflow/.local/lib/python3.12/site-packages/airflow/utils/session.py", line 97, in wrapper
    return func(*args, session=session, **kwargs)
           ^^^^^^^^^^^^^^^^^^^^^^^^^^^^^^^^^^^^^^
  File "/home/airflow/.local/lib/python3.12/site-packages/airflow/models/taskinstance.py", line 3004, in _run_raw_task
    return _run_raw_task(
           ^^^^^^^^^^^^^^
  File "/home/airflow/.local/lib/python3.12/site-packages/airflow/models/taskinstance.py", line 273, in _run_raw_task
    TaskInstance._execute_task_with_callbacks(
  File "/home/airflow/.local/lib/python3.12/site-packages/airflow/models/taskinstance.py", line 3158, in _execute_task_with_callbacks
    result = self._execute_task(context, task_orig)
             ^^^^^^^^^^^^^^^^^^^^^^^^^^^^^^^^^^^^^^
  File "/home/airflow/.local/lib/python3.12/site-packages/airflow/models/taskinstance.py", line 3182, in _execute_task
    return _execute_task(self, context, task_orig)
           ^^^^^^^^^^^^^^^^^^^^^^^^^^^^^^^^^^^^^^^
  File "/home/airflow/.local/lib/python3.12/site-packages/airflow/models/taskinstance.py", line 767, in _execute_task
    result = _execute_callable(context=context, **execute_callable_kwargs)
             ^^^^^^^^^^^^^^^^^^^^^^^^^^^^^^^^^^^^^^^^^^^^^^^^^^^^^^^^^^^^^
  File "/home/airflow/.local/lib/python3.12/site-packages/airflow/models/taskinstance.py", line 733, in _execute_callable
    return ExecutionCallableRunner(
           ^^^^^^^^^^^^^^^^^^^^^^^^
  File "/home/airflow/.local/lib/python3.12/site-packages/airflow/utils/operator_helpers.py", line 252, in run
    return self.func(*args, **kwargs)
           ^^^^^^^^^^^^^^^^^^^^^^^^^^
  File "/home/airflow/.local/lib/python3.12/site-packages/airflow/models/baseoperator.py", line 406, in wrapper
    return func(self, *args, **kwargs)
           ^^^^^^^^^^^^^^^^^^^^^^^^^^^
  File "/home/airflow/.local/lib/python3.12/site-packages/airflow/operators/bash.py", line 249, in execute
    raise AirflowException(
airflow.exceptions.AirflowException: Bash command failed. The command returned a non-zero exit code 1.
[2025-10-31T09:58:46.183+0000] {local_task_job_runner.py:266} INFO - Task exited with return code 1
[2025-10-31T09:58:46.202+0000] {taskinstance.py:3900} INFO - 0 downstream tasks scheduled from follow-on schedule check
[2025-10-31T09:58:46.207+0000] {local_task_job_runner.py:245} INFO - ::endgroup::
