[2025-10-30T16:00:45.423+0000] {local_task_job_runner.py:123} INFO - ::group::Pre task execution logs
[2025-10-30T16:00:45.443+0000] {taskinstance.py:2612} INFO - Dependencies all met for dep_context=non-requeueable deps ti=<TaskInstance: refresh_bike_db.refresh_bike_db scheduled__2025-10-30T15:59:00+00:00 [queued]>
[2025-10-30T16:00:45.454+0000] {taskinstance.py:2612} INFO - Dependencies all met for dep_context=requeueable deps ti=<TaskInstance: refresh_bike_db.refresh_bike_db scheduled__2025-10-30T15:59:00+00:00 [queued]>
[2025-10-30T16:00:45.456+0000] {taskinstance.py:2865} INFO - Starting attempt 2 of 2
[2025-10-30T16:00:45.474+0000] {taskinstance.py:2888} INFO - Executing <Task(BashOperator): refresh_bike_db> on 2025-10-30 15:59:00+00:00
[2025-10-30T16:00:45.481+0000] {logging_mixin.py:190} WARNING - /home/***/.local/lib/python3.12/site-packages/***/task/task_runner/standard_task_runner.py:70 DeprecationWarning: This process (pid=4468) is multi-threaded, use of fork() may lead to deadlocks in the child.
[2025-10-30T16:00:45.483+0000] {standard_task_runner.py:72} INFO - Started process 4469 to run task
[2025-10-30T16:00:45.483+0000] {standard_task_runner.py:104} INFO - Running: ['***', 'tasks', 'run', 'refresh_bike_db', 'refresh_bike_db', 'scheduled__2025-10-30T15:59:00+00:00', '--job-id', '293', '--raw', '--subdir', 'DAGS_FOLDER/refresh_bike_db.py', '--cfg-path', '/tmp/tmpqrjd7lye']
[2025-10-30T16:00:45.485+0000] {standard_task_runner.py:105} INFO - Job 293: Subtask refresh_bike_db
[2025-10-30T16:00:45.507+0000] {logging_mixin.py:190} WARNING - /home/***/.local/lib/python3.12/site-packages/***/settings.py:209 DeprecationWarning: The sql_alchemy_conn option in [core] has been moved to the sql_alchemy_conn option in [database] - the old setting has been used, but please update your config.
[2025-10-30T16:00:45.560+0000] {task_command.py:467} INFO - Running <TaskInstance: refresh_bike_db.refresh_bike_db scheduled__2025-10-30T15:59:00+00:00 [running]> on host 8e61f8c083ab
[2025-10-30T16:00:45.562+0000] {logging_mixin.py:190} WARNING - /home/***/.local/lib/python3.12/site-packages/***/settings.py:470 DeprecationWarning: The sql_alchemy_conn option in [core] has been moved to the sql_alchemy_conn option in [database] - the old setting has been used, but please update your config.
[2025-10-30T16:00:45.659+0000] {taskinstance.py:3131} INFO - Exporting env vars: AIRFLOW_CTX_DAG_OWNER='***' AIRFLOW_CTX_DAG_ID='refresh_bike_db' AIRFLOW_CTX_TASK_ID='refresh_bike_db' AIRFLOW_CTX_EXECUTION_DATE='2025-10-30T15:59:00+00:00' AIRFLOW_CTX_TRY_NUMBER='2' AIRFLOW_CTX_DAG_RUN_ID='scheduled__2025-10-30T15:59:00+00:00'
[2025-10-30T16:00:45.660+0000] {taskinstance.py:731} INFO - ::endgroup::
[2025-10-30T16:00:45.675+0000] {subprocess.py:63} INFO - Tmp dir root location: /tmp
[2025-10-30T16:00:45.677+0000] {subprocess.py:75} INFO - Running command: ['/usr/bin/bash', '-c', 'python -m pip install -r requirements.txt; python $AIRFLOW_HOME/plugins/gather_bike_data.py; python $AIRFLOW_HOME/plugins/app_flask.py']
[2025-10-30T16:00:45.685+0000] {subprocess.py:86} INFO - Output:
[2025-10-30T16:00:46.569+0000] {subprocess.py:93} INFO - 
[2025-10-30T16:00:46.570+0000] {subprocess.py:93} INFO - [notice] A new release of pip is available: 24.2 -> 25.3
[2025-10-30T16:00:46.572+0000] {subprocess.py:93} INFO - [notice] To update, run: pip install --upgrade pip
[2025-10-30T16:00:46.573+0000] {subprocess.py:93} INFO - ERROR: Could not open requirements file: [Errno 2] No such file or directory: 'requirements.txt'
[2025-10-30T16:00:54.700+0000] {subprocess.py:93} INFO - Fetching data of Lille's api: 302
[2025-10-30T16:00:54.701+0000] {subprocess.py:93} INFO - Fetching data of Paris's api: 1495
[2025-10-30T16:00:54.702+0000] {subprocess.py:93} INFO - 
[2025-10-30T16:00:54.703+0000] {subprocess.py:93} INFO - 
[2025-10-30T16:00:54.703+0000] {subprocess.py:93} INFO - ✅ Connected successfully to MySQL!
[2025-10-30T16:00:54.704+0000] {subprocess.py:93} INFO - ✅ Connected successfully to MySQL!
[2025-10-30T16:00:55.995+0000] {subprocess.py:93} INFO - Traceback (most recent call last):
[2025-10-30T16:00:55.996+0000] {subprocess.py:93} INFO -   File "/opt/***/plugins/app_flask.py", line 5, in <module>
[2025-10-30T16:00:55.998+0000] {subprocess.py:93} INFO -     import folium
[2025-10-30T16:00:55.999+0000] {subprocess.py:93} INFO - ModuleNotFoundError: No module named 'folium'
[2025-10-30T16:00:56.143+0000] {subprocess.py:97} INFO - Command exited with return code 1
[2025-10-30T16:00:56.164+0000] {taskinstance.py:3310} ERROR - Task failed with exception
Traceback (most recent call last):
  File "/home/airflow/.local/lib/python3.12/site-packages/airflow/models/taskinstance.py", line 767, in _execute_task
    result = _execute_callable(context=context, **execute_callable_kwargs)
             ^^^^^^^^^^^^^^^^^^^^^^^^^^^^^^^^^^^^^^^^^^^^^^^^^^^^^^^^^^^^^
  File "/home/airflow/.local/lib/python3.12/site-packages/airflow/models/taskinstance.py", line 733, in _execute_callable
    return ExecutionCallableRunner(
           ^^^^^^^^^^^^^^^^^^^^^^^^
  File "/home/airflow/.local/lib/python3.12/site-packages/airflow/utils/operator_helpers.py", line 252, in run
    return self.func(*args, **kwargs)
           ^^^^^^^^^^^^^^^^^^^^^^^^^^
  File "/home/airflow/.local/lib/python3.12/site-packages/airflow/models/baseoperator.py", line 406, in wrapper
    return func(self, *args, **kwargs)
           ^^^^^^^^^^^^^^^^^^^^^^^^^^^
  File "/home/airflow/.local/lib/python3.12/site-packages/airflow/operators/bash.py", line 249, in execute
    raise AirflowException(
airflow.exceptions.AirflowException: Bash command failed. The command returned a non-zero exit code 1.
[2025-10-30T16:00:56.171+0000] {taskinstance.py:1225} INFO - Marking task as FAILED. dag_id=refresh_bike_db, task_id=refresh_bike_db, run_id=scheduled__2025-10-30T15:59:00+00:00, execution_date=20251030T155900, start_date=20251030T160045, end_date=20251030T160056
[2025-10-30T16:00:56.191+0000] {taskinstance.py:340} INFO - ::group::Post task execution logs
[2025-10-30T16:00:56.192+0000] {standard_task_runner.py:124} ERROR - Failed to execute job 293 for task refresh_bike_db (Bash command failed. The command returned a non-zero exit code 1.; 4469)
Traceback (most recent call last):
  File "/home/airflow/.local/lib/python3.12/site-packages/airflow/task/task_runner/standard_task_runner.py", line 117, in _start_by_fork
    ret = args.func(args, dag=self.dag)
          ^^^^^^^^^^^^^^^^^^^^^^^^^^^^^
  File "/home/airflow/.local/lib/python3.12/site-packages/airflow/cli/cli_config.py", line 49, in command
    return func(*args, **kwargs)
           ^^^^^^^^^^^^^^^^^^^^^
  File "/home/airflow/.local/lib/python3.12/site-packages/airflow/utils/cli.py", line 115, in wrapper
    return f(*args, **kwargs)
           ^^^^^^^^^^^^^^^^^^
  File "/home/airflow/.local/lib/python3.12/site-packages/airflow/cli/commands/task_command.py", line 483, in task_run
    task_return_code = _run_task_by_selected_method(args, _dag, ti)
                       ^^^^^^^^^^^^^^^^^^^^^^^^^^^^^^^^^^^^^^^^^^^^
  File "/home/airflow/.local/lib/python3.12/site-packages/airflow/cli/commands/task_command.py", line 256, in _run_task_by_selected_method
    return _run_raw_task(args, ti)
           ^^^^^^^^^^^^^^^^^^^^^^^
  File "/home/airflow/.local/lib/python3.12/site-packages/airflow/cli/commands/task_command.py", line 341, in _run_raw_task
    return ti._run_raw_task(
           ^^^^^^^^^^^^^^^^^
  File "/home/airflow/.local/lib/python3.12/site-packages/airflow/utils/session.py", line 97, in wrapper
    return func(*args, session=session, **kwargs)
           ^^^^^^^^^^^^^^^^^^^^^^^^^^^^^^^^^^^^^^
  File "/home/airflow/.local/lib/python3.12/site-packages/airflow/models/taskinstance.py", line 3004, in _run_raw_task
    return _run_raw_task(
           ^^^^^^^^^^^^^^
  File "/home/airflow/.local/lib/python3.12/site-packages/airflow/models/taskinstance.py", line 273, in _run_raw_task
    TaskInstance._execute_task_with_callbacks(
  File "/home/airflow/.local/lib/python3.12/site-packages/airflow/models/taskinstance.py", line 3158, in _execute_task_with_callbacks
    result = self._execute_task(context, task_orig)
             ^^^^^^^^^^^^^^^^^^^^^^^^^^^^^^^^^^^^^^
  File "/home/airflow/.local/lib/python3.12/site-packages/airflow/models/taskinstance.py", line 3182, in _execute_task
    return _execute_task(self, context, task_orig)
           ^^^^^^^^^^^^^^^^^^^^^^^^^^^^^^^^^^^^^^^
  File "/home/airflow/.local/lib/python3.12/site-packages/airflow/models/taskinstance.py", line 767, in _execute_task
    result = _execute_callable(context=context, **execute_callable_kwargs)
             ^^^^^^^^^^^^^^^^^^^^^^^^^^^^^^^^^^^^^^^^^^^^^^^^^^^^^^^^^^^^^
  File "/home/airflow/.local/lib/python3.12/site-packages/airflow/models/taskinstance.py", line 733, in _execute_callable
    return ExecutionCallableRunner(
           ^^^^^^^^^^^^^^^^^^^^^^^^
  File "/home/airflow/.local/lib/python3.12/site-packages/airflow/utils/operator_helpers.py", line 252, in run
    return self.func(*args, **kwargs)
           ^^^^^^^^^^^^^^^^^^^^^^^^^^
  File "/home/airflow/.local/lib/python3.12/site-packages/airflow/models/baseoperator.py", line 406, in wrapper
    return func(self, *args, **kwargs)
           ^^^^^^^^^^^^^^^^^^^^^^^^^^^
  File "/home/airflow/.local/lib/python3.12/site-packages/airflow/operators/bash.py", line 249, in execute
    raise AirflowException(
airflow.exceptions.AirflowException: Bash command failed. The command returned a non-zero exit code 1.
[2025-10-30T16:00:56.215+0000] {local_task_job_runner.py:266} INFO - Task exited with return code 1
[2025-10-30T16:00:56.236+0000] {taskinstance.py:3900} INFO - 0 downstream tasks scheduled from follow-on schedule check
[2025-10-30T16:00:56.240+0000] {local_task_job_runner.py:245} INFO - ::endgroup::
