[2025-10-31T14:28:01.238+0000] {local_task_job_runner.py:123} INFO - ::group::Pre task execution logs
[2025-10-31T14:28:01.258+0000] {taskinstance.py:2612} INFO - Dependencies all met for dep_context=non-requeueable deps ti=<TaskInstance: refresh_bike_db.refresh_bike_db scheduled__2025-10-31T14:27:00+00:00 [queued]>
[2025-10-31T14:28:01.268+0000] {taskinstance.py:2612} INFO - Dependencies all met for dep_context=requeueable deps ti=<TaskInstance: refresh_bike_db.refresh_bike_db scheduled__2025-10-31T14:27:00+00:00 [queued]>
[2025-10-31T14:28:01.270+0000] {taskinstance.py:2865} INFO - Starting attempt 1 of 2
[2025-10-31T14:28:01.288+0000] {taskinstance.py:2888} INFO - Executing <Task(BashOperator): refresh_bike_db> on 2025-10-31 14:27:00+00:00
[2025-10-31T14:28:01.302+0000] {standard_task_runner.py:104} INFO - Running: ['***', 'tasks', 'run', 'refresh_bike_db', 'refresh_bike_db', 'scheduled__2025-10-31T14:27:00+00:00', '--job-id', '566', '--raw', '--subdir', 'DAGS_FOLDER/refresh_bike_db.py', '--cfg-path', '/tmp/tmp8ypc0mx5']
[2025-10-31T14:28:01.304+0000] {standard_task_runner.py:105} INFO - Job 566: Subtask refresh_bike_db
[2025-10-31T14:28:01.305+0000] {logging_mixin.py:190} WARNING - /home/***/.local/lib/python3.12/site-packages/***/task/task_runner/standard_task_runner.py:70 DeprecationWarning: This process (pid=1090) is multi-threaded, use of fork() may lead to deadlocks in the child.
[2025-10-31T14:28:01.307+0000] {standard_task_runner.py:72} INFO - Started process 1091 to run task
[2025-10-31T14:28:01.379+0000] {task_command.py:467} INFO - Running <TaskInstance: refresh_bike_db.refresh_bike_db scheduled__2025-10-31T14:27:00+00:00 [running]> on host 94513e024ddd
[2025-10-31T14:28:01.494+0000] {taskinstance.py:3131} INFO - Exporting env vars: AIRFLOW_CTX_DAG_OWNER='***' AIRFLOW_CTX_DAG_ID='refresh_bike_db' AIRFLOW_CTX_TASK_ID='refresh_bike_db' AIRFLOW_CTX_EXECUTION_DATE='2025-10-31T14:27:00+00:00' AIRFLOW_CTX_TRY_NUMBER='1' AIRFLOW_CTX_DAG_RUN_ID='scheduled__2025-10-31T14:27:00+00:00'
[2025-10-31T14:28:01.495+0000] {taskinstance.py:731} INFO - ::endgroup::
[2025-10-31T14:28:01.512+0000] {subprocess.py:63} INFO - Tmp dir root location: /tmp
[2025-10-31T14:28:01.514+0000] {subprocess.py:75} INFO - Running command: ['/usr/bin/bash', '-c', '\n          set -euxo pipefail\n          cd "$AIRFLOW_HOME/plugins"\n          python gather_bike_data.py\n        ']
[2025-10-31T14:28:01.528+0000] {subprocess.py:86} INFO - Output:
[2025-10-31T14:28:01.529+0000] {subprocess.py:93} INFO - + cd /opt/***/plugins
[2025-10-31T14:28:01.530+0000] {subprocess.py:93} INFO - + python gather_bike_data.py
[2025-10-31T14:28:03.831+0000] {subprocess.py:93} INFO - Fetching data of Lille's api: 302
[2025-10-31T14:28:03.891+0000] {subprocess.py:93} INFO - Traceback (most recent call last):
[2025-10-31T14:28:03.903+0000] {subprocess.py:93} INFO -   File "/home/***/.local/lib/python3.12/site-packages/urllib3/connectionpool.py", line 466, in _make_request
[2025-10-31T14:28:03.919+0000] {subprocess.py:93} INFO -     self._validate_conn(conn)
[2025-10-31T14:28:03.925+0000] {subprocess.py:93} INFO -   File "/home/***/.local/lib/python3.12/site-packages/urllib3/connectionpool.py", line 1095, in _validate_conn
[2025-10-31T14:28:03.931+0000] {subprocess.py:93} INFO -     conn.connect()
[2025-10-31T14:28:03.938+0000] {subprocess.py:93} INFO -   File "/home/***/.local/lib/python3.12/site-packages/urllib3/connection.py", line 652, in connect
[2025-10-31T14:28:03.951+0000] {subprocess.py:93} INFO -     sock_and_verified = _ssl_wrap_socket_and_match_hostname(
[2025-10-31T14:28:03.968+0000] {subprocess.py:93} INFO -                         ^^^^^^^^^^^^^^^^^^^^^^^^^^^^^^^^^^^^
[2025-10-31T14:28:03.975+0000] {subprocess.py:93} INFO -   File "/home/***/.local/lib/python3.12/site-packages/urllib3/connection.py", line 805, in _ssl_wrap_socket_and_match_hostname
[2025-10-31T14:28:03.983+0000] {subprocess.py:93} INFO -     ssl_sock = ssl_wrap_socket(
[2025-10-31T14:28:03.986+0000] {subprocess.py:93} INFO -                ^^^^^^^^^^^^^^^^
[2025-10-31T14:28:03.992+0000] {subprocess.py:93} INFO -   File "/home/***/.local/lib/python3.12/site-packages/urllib3/util/ssl_.py", line 465, in ssl_wrap_socket
[2025-10-31T14:28:03.998+0000] {subprocess.py:93} INFO -     ssl_sock = _ssl_wrap_socket_impl(sock, context, tls_in_tls, server_hostname)
[2025-10-31T14:28:04.002+0000] {subprocess.py:93} INFO -                ^^^^^^^^^^^^^^^^^^^^^^^^^^^^^^^^^^^^^^^^^^^^^^^^^^^^^^^^^^^^^^^^^
[2025-10-31T14:28:04.003+0000] {subprocess.py:93} INFO -   File "/home/***/.local/lib/python3.12/site-packages/urllib3/util/ssl_.py", line 509, in _ssl_wrap_socket_impl
[2025-10-31T14:28:04.004+0000] {subprocess.py:93} INFO -     return ssl_context.wrap_socket(sock, server_hostname=server_hostname)
[2025-10-31T14:28:04.005+0000] {subprocess.py:93} INFO -            ^^^^^^^^^^^^^^^^^^^^^^^^^^^^^^^^^^^^^^^^^^^^^^^^^^^^^^^^^^^^^^
[2025-10-31T14:28:04.006+0000] {subprocess.py:93} INFO -   File "/usr/local/lib/python3.12/ssl.py", line 455, in wrap_socket
[2025-10-31T14:28:04.009+0000] {subprocess.py:93} INFO -     return self.sslsocket_class._create(
[2025-10-31T14:28:04.011+0000] {subprocess.py:93} INFO -            ^^^^^^^^^^^^^^^^^^^^^^^^^^^^^
[2025-10-31T14:28:04.014+0000] {subprocess.py:93} INFO -   File "/usr/local/lib/python3.12/ssl.py", line 1041, in _create
[2025-10-31T14:28:04.016+0000] {subprocess.py:93} INFO -     self.do_handshake()
[2025-10-31T14:28:04.020+0000] {subprocess.py:93} INFO -   File "/usr/local/lib/python3.12/ssl.py", line 1319, in do_handshake
[2025-10-31T14:28:04.022+0000] {subprocess.py:93} INFO -     self._sslobj.do_handshake()
[2025-10-31T14:28:04.024+0000] {subprocess.py:93} INFO - ssl.SSLEOFError: [SSL: UNEXPECTED_EOF_WHILE_READING] EOF occurred in violation of protocol (_ssl.c:1000)
[2025-10-31T14:28:04.025+0000] {subprocess.py:93} INFO - 
[2025-10-31T14:28:04.026+0000] {subprocess.py:93} INFO - During handling of the above exception, another exception occurred:
[2025-10-31T14:28:04.034+0000] {subprocess.py:93} INFO - 
[2025-10-31T14:28:04.037+0000] {subprocess.py:93} INFO - Traceback (most recent call last):
[2025-10-31T14:28:04.039+0000] {subprocess.py:93} INFO -   File "/home/***/.local/lib/python3.12/site-packages/urllib3/connectionpool.py", line 789, in urlopen
[2025-10-31T14:28:04.040+0000] {subprocess.py:93} INFO -     response = self._make_request(
[2025-10-31T14:28:04.041+0000] {subprocess.py:93} INFO -                ^^^^^^^^^^^^^^^^^^^
[2025-10-31T14:28:04.042+0000] {subprocess.py:93} INFO -   File "/home/***/.local/lib/python3.12/site-packages/urllib3/connectionpool.py", line 490, in _make_request
[2025-10-31T14:28:04.043+0000] {subprocess.py:93} INFO -     raise new_e
[2025-10-31T14:28:04.043+0000] {subprocess.py:93} INFO - urllib3.exceptions.SSLError: [SSL: UNEXPECTED_EOF_WHILE_READING] EOF occurred in violation of protocol (_ssl.c:1000)
[2025-10-31T14:28:04.044+0000] {subprocess.py:93} INFO - 
[2025-10-31T14:28:04.045+0000] {subprocess.py:93} INFO - The above exception was the direct cause of the following exception:
[2025-10-31T14:28:04.046+0000] {subprocess.py:93} INFO - 
[2025-10-31T14:28:04.050+0000] {subprocess.py:93} INFO - Traceback (most recent call last):
[2025-10-31T14:28:04.051+0000] {subprocess.py:93} INFO -   File "/home/***/.local/lib/python3.12/site-packages/requests/adapters.py", line 667, in send
[2025-10-31T14:28:04.052+0000] {subprocess.py:93} INFO -     resp = conn.urlopen(
[2025-10-31T14:28:04.053+0000] {subprocess.py:93} INFO -            ^^^^^^^^^^^^^
[2025-10-31T14:28:04.053+0000] {subprocess.py:93} INFO -   File "/home/***/.local/lib/python3.12/site-packages/urllib3/connectionpool.py", line 843, in urlopen
[2025-10-31T14:28:04.054+0000] {subprocess.py:93} INFO -     retries = retries.increment(
[2025-10-31T14:28:04.055+0000] {subprocess.py:93} INFO -               ^^^^^^^^^^^^^^^^^^
[2025-10-31T14:28:04.057+0000] {subprocess.py:93} INFO -   File "/home/***/.local/lib/python3.12/site-packages/urllib3/util/retry.py", line 519, in increment
[2025-10-31T14:28:04.058+0000] {subprocess.py:93} INFO -     raise MaxRetryError(_pool, url, reason) from reason  # type: ignore[arg-type]
[2025-10-31T14:28:04.060+0000] {subprocess.py:93} INFO -     ^^^^^^^^^^^^^^^^^^^^^^^^^^^^^^^^^^^^^^^^^^^^^^^^^^^
[2025-10-31T14:28:04.061+0000] {subprocess.py:93} INFO - urllib3.exceptions.MaxRetryError: HTTPSConnectionPool(host='opendata.paris.fr', port=443): Max retries exceeded with url: /api/explore/v2.1/catalog/datasets/velib-disponibilite-en-temps-reel/records?limit=100&offset=0 (Caused by SSLError(SSLEOFError(8, '[SSL: UNEXPECTED_EOF_WHILE_READING] EOF occurred in violation of protocol (_ssl.c:1000)')))
[2025-10-31T14:28:04.062+0000] {subprocess.py:93} INFO - 
[2025-10-31T14:28:04.068+0000] {subprocess.py:93} INFO - During handling of the above exception, another exception occurred:
[2025-10-31T14:28:04.069+0000] {subprocess.py:93} INFO - 
[2025-10-31T14:28:04.069+0000] {subprocess.py:93} INFO - Traceback (most recent call last):
[2025-10-31T14:28:04.070+0000] {subprocess.py:93} INFO -   File "/opt/***/plugins/gather_bike_data.py", line 293, in <module>
[2025-10-31T14:28:04.074+0000] {subprocess.py:93} INFO -     df = global_dataframe()
[2025-10-31T14:28:04.076+0000] {subprocess.py:93} INFO -          ^^^^^^^^^^^^^^^^^^
[2025-10-31T14:28:04.081+0000] {subprocess.py:93} INFO -   File "/opt/***/plugins/gather_bike_data.py", line 247, in global_dataframe
[2025-10-31T14:28:04.083+0000] {subprocess.py:93} INFO -     data_paris = fetch_paris_bike_data()
[2025-10-31T14:28:04.084+0000] {subprocess.py:93} INFO -                  ^^^^^^^^^^^^^^^^^^^^^^^
[2025-10-31T14:28:04.085+0000] {subprocess.py:93} INFO -   File "/opt/***/plugins/gather_bike_data.py", line 225, in fetch_paris_bike_data
[2025-10-31T14:28:04.090+0000] {subprocess.py:93} INFO -     r = requests.get(url)
[2025-10-31T14:28:04.091+0000] {subprocess.py:93} INFO -         ^^^^^^^^^^^^^^^^^
[2025-10-31T14:28:04.092+0000] {subprocess.py:93} INFO -   File "/home/***/.local/lib/python3.12/site-packages/requests/api.py", line 73, in get
[2025-10-31T14:28:04.093+0000] {subprocess.py:93} INFO -     return request("get", url, params=params, **kwargs)
[2025-10-31T14:28:04.094+0000] {subprocess.py:93} INFO -            ^^^^^^^^^^^^^^^^^^^^^^^^^^^^^^^^^^^^^^^^^^^^
[2025-10-31T14:28:04.095+0000] {subprocess.py:93} INFO -   File "/home/***/.local/lib/python3.12/site-packages/requests/api.py", line 59, in request
[2025-10-31T14:28:04.097+0000] {subprocess.py:93} INFO -     return session.request(method=method, url=url, **kwargs)
[2025-10-31T14:28:04.100+0000] {subprocess.py:93} INFO -            ^^^^^^^^^^^^^^^^^^^^^^^^^^^^^^^^^^^^^^^^^^^^^^^^^
[2025-10-31T14:28:04.111+0000] {subprocess.py:93} INFO -   File "/home/***/.local/lib/python3.12/site-packages/requests/sessions.py", line 589, in request
[2025-10-31T14:28:04.116+0000] {subprocess.py:93} INFO -     resp = self.send(prep, **send_kwargs)
[2025-10-31T14:28:04.119+0000] {subprocess.py:93} INFO -            ^^^^^^^^^^^^^^^^^^^^^^^^^^^^^^
[2025-10-31T14:28:04.122+0000] {subprocess.py:93} INFO -   File "/home/***/.local/lib/python3.12/site-packages/requests/sessions.py", line 703, in send
[2025-10-31T14:28:04.125+0000] {subprocess.py:93} INFO -     r = adapter.send(request, **kwargs)
[2025-10-31T14:28:04.126+0000] {subprocess.py:93} INFO -         ^^^^^^^^^^^^^^^^^^^^^^^^^^^^^^^
[2025-10-31T14:28:04.126+0000] {subprocess.py:93} INFO -   File "/home/***/.local/lib/python3.12/site-packages/requests/adapters.py", line 698, in send
[2025-10-31T14:28:04.127+0000] {subprocess.py:93} INFO -     raise SSLError(e, request=request)
[2025-10-31T14:28:04.129+0000] {subprocess.py:93} INFO - requests.exceptions.SSLError: HTTPSConnectionPool(host='opendata.paris.fr', port=443): Max retries exceeded with url: /api/explore/v2.1/catalog/datasets/velib-disponibilite-en-temps-reel/records?limit=100&offset=0 (Caused by SSLError(SSLEOFError(8, '[SSL: UNEXPECTED_EOF_WHILE_READING] EOF occurred in violation of protocol (_ssl.c:1000)')))
[2025-10-31T14:28:04.364+0000] {subprocess.py:97} INFO - Command exited with return code 1
[2025-10-31T14:28:04.389+0000] {taskinstance.py:3310} ERROR - Task failed with exception
Traceback (most recent call last):
  File "/home/airflow/.local/lib/python3.12/site-packages/airflow/models/taskinstance.py", line 767, in _execute_task
    result = _execute_callable(context=context, **execute_callable_kwargs)
             ^^^^^^^^^^^^^^^^^^^^^^^^^^^^^^^^^^^^^^^^^^^^^^^^^^^^^^^^^^^^^
  File "/home/airflow/.local/lib/python3.12/site-packages/airflow/models/taskinstance.py", line 733, in _execute_callable
    return ExecutionCallableRunner(
           ^^^^^^^^^^^^^^^^^^^^^^^^
  File "/home/airflow/.local/lib/python3.12/site-packages/airflow/utils/operator_helpers.py", line 252, in run
    return self.func(*args, **kwargs)
           ^^^^^^^^^^^^^^^^^^^^^^^^^^
  File "/home/airflow/.local/lib/python3.12/site-packages/airflow/models/baseoperator.py", line 406, in wrapper
    return func(self, *args, **kwargs)
           ^^^^^^^^^^^^^^^^^^^^^^^^^^^
  File "/home/airflow/.local/lib/python3.12/site-packages/airflow/operators/bash.py", line 249, in execute
    raise AirflowException(
airflow.exceptions.AirflowException: Bash command failed. The command returned a non-zero exit code 1.
[2025-10-31T14:28:04.435+0000] {taskinstance.py:1225} INFO - Marking task as UP_FOR_RETRY. dag_id=refresh_bike_db, task_id=refresh_bike_db, run_id=scheduled__2025-10-31T14:27:00+00:00, execution_date=20251031T142700, start_date=20251031T142801, end_date=20251031T142804
[2025-10-31T14:28:04.503+0000] {taskinstance.py:340} INFO - ::group::Post task execution logs
[2025-10-31T14:28:04.504+0000] {standard_task_runner.py:124} ERROR - Failed to execute job 566 for task refresh_bike_db (Bash command failed. The command returned a non-zero exit code 1.; 1091)
Traceback (most recent call last):
  File "/home/airflow/.local/lib/python3.12/site-packages/airflow/task/task_runner/standard_task_runner.py", line 117, in _start_by_fork
    ret = args.func(args, dag=self.dag)
          ^^^^^^^^^^^^^^^^^^^^^^^^^^^^^
  File "/home/airflow/.local/lib/python3.12/site-packages/airflow/cli/cli_config.py", line 49, in command
    return func(*args, **kwargs)
           ^^^^^^^^^^^^^^^^^^^^^
  File "/home/airflow/.local/lib/python3.12/site-packages/airflow/utils/cli.py", line 115, in wrapper
    return f(*args, **kwargs)
           ^^^^^^^^^^^^^^^^^^
  File "/home/airflow/.local/lib/python3.12/site-packages/airflow/cli/commands/task_command.py", line 483, in task_run
    task_return_code = _run_task_by_selected_method(args, _dag, ti)
                       ^^^^^^^^^^^^^^^^^^^^^^^^^^^^^^^^^^^^^^^^^^^^
  File "/home/airflow/.local/lib/python3.12/site-packages/airflow/cli/commands/task_command.py", line 256, in _run_task_by_selected_method
    return _run_raw_task(args, ti)
           ^^^^^^^^^^^^^^^^^^^^^^^
  File "/home/airflow/.local/lib/python3.12/site-packages/airflow/cli/commands/task_command.py", line 341, in _run_raw_task
    return ti._run_raw_task(
           ^^^^^^^^^^^^^^^^^
  File "/home/airflow/.local/lib/python3.12/site-packages/airflow/utils/session.py", line 97, in wrapper
    return func(*args, session=session, **kwargs)
           ^^^^^^^^^^^^^^^^^^^^^^^^^^^^^^^^^^^^^^
  File "/home/airflow/.local/lib/python3.12/site-packages/airflow/models/taskinstance.py", line 3004, in _run_raw_task
    return _run_raw_task(
           ^^^^^^^^^^^^^^
  File "/home/airflow/.local/lib/python3.12/site-packages/airflow/models/taskinstance.py", line 273, in _run_raw_task
    TaskInstance._execute_task_with_callbacks(
  File "/home/airflow/.local/lib/python3.12/site-packages/airflow/models/taskinstance.py", line 3158, in _execute_task_with_callbacks
    result = self._execute_task(context, task_orig)
             ^^^^^^^^^^^^^^^^^^^^^^^^^^^^^^^^^^^^^^
  File "/home/airflow/.local/lib/python3.12/site-packages/airflow/models/taskinstance.py", line 3182, in _execute_task
    return _execute_task(self, context, task_orig)
           ^^^^^^^^^^^^^^^^^^^^^^^^^^^^^^^^^^^^^^^
  File "/home/airflow/.local/lib/python3.12/site-packages/airflow/models/taskinstance.py", line 767, in _execute_task
    result = _execute_callable(context=context, **execute_callable_kwargs)
             ^^^^^^^^^^^^^^^^^^^^^^^^^^^^^^^^^^^^^^^^^^^^^^^^^^^^^^^^^^^^^
  File "/home/airflow/.local/lib/python3.12/site-packages/airflow/models/taskinstance.py", line 733, in _execute_callable
    return ExecutionCallableRunner(
           ^^^^^^^^^^^^^^^^^^^^^^^^
  File "/home/airflow/.local/lib/python3.12/site-packages/airflow/utils/operator_helpers.py", line 252, in run
    return self.func(*args, **kwargs)
           ^^^^^^^^^^^^^^^^^^^^^^^^^^
  File "/home/airflow/.local/lib/python3.12/site-packages/airflow/models/baseoperator.py", line 406, in wrapper
    return func(self, *args, **kwargs)
           ^^^^^^^^^^^^^^^^^^^^^^^^^^^
  File "/home/airflow/.local/lib/python3.12/site-packages/airflow/operators/bash.py", line 249, in execute
    raise AirflowException(
airflow.exceptions.AirflowException: Bash command failed. The command returned a non-zero exit code 1.
[2025-10-31T14:28:04.576+0000] {local_task_job_runner.py:266} INFO - Task exited with return code 1
[2025-10-31T14:28:04.621+0000] {taskinstance.py:3900} INFO - 0 downstream tasks scheduled from follow-on schedule check
[2025-10-31T14:28:04.627+0000] {local_task_job_runner.py:245} INFO - ::endgroup::
