[2025-10-30T15:10:43.004+0000] {local_task_job_runner.py:123} INFO - ::group::Pre task execution logs
[2025-10-30T15:10:43.032+0000] {taskinstance.py:2612} INFO - Dependencies all met for dep_context=non-requeueable deps ti=<TaskInstance: refresh_bike_db.refresh_bike_db manual__2025-10-30T15:10:41.689546+00:00 [queued]>
[2025-10-30T15:10:43.046+0000] {taskinstance.py:2612} INFO - Dependencies all met for dep_context=requeueable deps ti=<TaskInstance: refresh_bike_db.refresh_bike_db manual__2025-10-30T15:10:41.689546+00:00 [queued]>
[2025-10-30T15:10:43.047+0000] {taskinstance.py:2865} INFO - Starting attempt 1 of 2
[2025-10-30T15:10:43.066+0000] {taskinstance.py:2888} INFO - Executing <Task(BashOperator): refresh_bike_db> on 2025-10-30 15:10:41.689546+00:00
[2025-10-30T15:10:43.080+0000] {logging_mixin.py:190} WARNING - /home/***/.local/lib/python3.12/site-packages/***/task/task_runner/standard_task_runner.py:70 DeprecationWarning: This process (pid=2547) is multi-threaded, use of fork() may lead to deadlocks in the child.
[2025-10-30T15:10:43.078+0000] {standard_task_runner.py:104} INFO - Running: ['***', 'tasks', 'run', 'refresh_bike_db', 'refresh_bike_db', 'manual__2025-10-30T15:10:41.689546+00:00', '--job-id', '215', '--raw', '--subdir', 'DAGS_FOLDER/refresh_bike_db.py', '--cfg-path', '/tmp/tmpy5uxkme8']
[2025-10-30T15:10:43.082+0000] {standard_task_runner.py:72} INFO - Started process 2548 to run task
[2025-10-30T15:10:43.082+0000] {standard_task_runner.py:105} INFO - Job 215: Subtask refresh_bike_db
[2025-10-30T15:10:43.108+0000] {logging_mixin.py:190} WARNING - /home/***/.local/lib/python3.12/site-packages/***/settings.py:209 DeprecationWarning: The sql_alchemy_conn option in [core] has been moved to the sql_alchemy_conn option in [database] - the old setting has been used, but please update your config.
[2025-10-30T15:10:43.164+0000] {task_command.py:467} INFO - Running <TaskInstance: refresh_bike_db.refresh_bike_db manual__2025-10-30T15:10:41.689546+00:00 [running]> on host 8e61f8c083ab
[2025-10-30T15:10:43.307+0000] {taskinstance.py:3131} INFO - Exporting env vars: AIRFLOW_CTX_DAG_OWNER='***' AIRFLOW_CTX_DAG_ID='refresh_bike_db' AIRFLOW_CTX_TASK_ID='refresh_bike_db' AIRFLOW_CTX_EXECUTION_DATE='2025-10-30T15:10:41.689546+00:00' AIRFLOW_CTX_TRY_NUMBER='1' AIRFLOW_CTX_DAG_RUN_ID='manual__2025-10-30T15:10:41.689546+00:00'
[2025-10-30T15:10:43.309+0000] {taskinstance.py:731} INFO - ::endgroup::
[2025-10-30T15:10:43.335+0000] {subprocess.py:63} INFO - Tmp dir root location: /tmp
[2025-10-30T15:10:43.339+0000] {subprocess.py:75} INFO - Running command: ['/usr/bin/bash', '-c', 'set -euxo pipefail; python $AIRFLOW_HOME/plugins/gather_bike_data.py']
[2025-10-30T15:10:43.349+0000] {subprocess.py:86} INFO - Output:
[2025-10-30T15:10:43.351+0000] {subprocess.py:93} INFO - + python /opt/***/plugins/gather_bike_data.py
[2025-10-30T15:10:43.410+0000] {subprocess.py:93} INFO - Traceback (most recent call last):
[2025-10-30T15:10:43.411+0000] {subprocess.py:93} INFO -   File "/opt/***/plugins/gather_bike_data.py", line 2, in <module>
[2025-10-30T15:10:43.413+0000] {subprocess.py:93} INFO -     import pymysql
[2025-10-30T15:10:43.413+0000] {subprocess.py:93} INFO - ModuleNotFoundError: No module named 'pymysql'
[2025-10-30T15:10:43.416+0000] {subprocess.py:97} INFO - Command exited with return code 1
[2025-10-30T15:10:43.434+0000] {taskinstance.py:3310} ERROR - Task failed with exception
Traceback (most recent call last):
  File "/home/airflow/.local/lib/python3.12/site-packages/airflow/models/taskinstance.py", line 767, in _execute_task
    result = _execute_callable(context=context, **execute_callable_kwargs)
             ^^^^^^^^^^^^^^^^^^^^^^^^^^^^^^^^^^^^^^^^^^^^^^^^^^^^^^^^^^^^^
  File "/home/airflow/.local/lib/python3.12/site-packages/airflow/models/taskinstance.py", line 733, in _execute_callable
    return ExecutionCallableRunner(
           ^^^^^^^^^^^^^^^^^^^^^^^^
  File "/home/airflow/.local/lib/python3.12/site-packages/airflow/utils/operator_helpers.py", line 252, in run
    return self.func(*args, **kwargs)
           ^^^^^^^^^^^^^^^^^^^^^^^^^^
  File "/home/airflow/.local/lib/python3.12/site-packages/airflow/models/baseoperator.py", line 406, in wrapper
    return func(self, *args, **kwargs)
           ^^^^^^^^^^^^^^^^^^^^^^^^^^^
  File "/home/airflow/.local/lib/python3.12/site-packages/airflow/operators/bash.py", line 249, in execute
    raise AirflowException(
airflow.exceptions.AirflowException: Bash command failed. The command returned a non-zero exit code 1.
[2025-10-30T15:10:43.446+0000] {taskinstance.py:1225} INFO - Marking task as UP_FOR_RETRY. dag_id=refresh_bike_db, task_id=refresh_bike_db, run_id=manual__2025-10-30T15:10:41.689546+00:00, execution_date=20251030T151041, start_date=20251030T151043, end_date=20251030T151043
[2025-10-30T15:10:43.477+0000] {taskinstance.py:340} INFO - ::group::Post task execution logs
[2025-10-30T15:10:43.478+0000] {standard_task_runner.py:124} ERROR - Failed to execute job 215 for task refresh_bike_db (Bash command failed. The command returned a non-zero exit code 1.; 2548)
Traceback (most recent call last):
  File "/home/airflow/.local/lib/python3.12/site-packages/airflow/task/task_runner/standard_task_runner.py", line 117, in _start_by_fork
    ret = args.func(args, dag=self.dag)
          ^^^^^^^^^^^^^^^^^^^^^^^^^^^^^
  File "/home/airflow/.local/lib/python3.12/site-packages/airflow/cli/cli_config.py", line 49, in command
    return func(*args, **kwargs)
           ^^^^^^^^^^^^^^^^^^^^^
  File "/home/airflow/.local/lib/python3.12/site-packages/airflow/utils/cli.py", line 115, in wrapper
    return f(*args, **kwargs)
           ^^^^^^^^^^^^^^^^^^
  File "/home/airflow/.local/lib/python3.12/site-packages/airflow/cli/commands/task_command.py", line 483, in task_run
    task_return_code = _run_task_by_selected_method(args, _dag, ti)
                       ^^^^^^^^^^^^^^^^^^^^^^^^^^^^^^^^^^^^^^^^^^^^
  File "/home/airflow/.local/lib/python3.12/site-packages/airflow/cli/commands/task_command.py", line 256, in _run_task_by_selected_method
    return _run_raw_task(args, ti)
           ^^^^^^^^^^^^^^^^^^^^^^^
  File "/home/airflow/.local/lib/python3.12/site-packages/airflow/cli/commands/task_command.py", line 341, in _run_raw_task
    return ti._run_raw_task(
           ^^^^^^^^^^^^^^^^^
  File "/home/airflow/.local/lib/python3.12/site-packages/airflow/utils/session.py", line 97, in wrapper
    return func(*args, session=session, **kwargs)
           ^^^^^^^^^^^^^^^^^^^^^^^^^^^^^^^^^^^^^^
  File "/home/airflow/.local/lib/python3.12/site-packages/airflow/models/taskinstance.py", line 3004, in _run_raw_task
    return _run_raw_task(
           ^^^^^^^^^^^^^^
  File "/home/airflow/.local/lib/python3.12/site-packages/airflow/models/taskinstance.py", line 273, in _run_raw_task
    TaskInstance._execute_task_with_callbacks(
  File "/home/airflow/.local/lib/python3.12/site-packages/airflow/models/taskinstance.py", line 3158, in _execute_task_with_callbacks
    result = self._execute_task(context, task_orig)
             ^^^^^^^^^^^^^^^^^^^^^^^^^^^^^^^^^^^^^^
  File "/home/airflow/.local/lib/python3.12/site-packages/airflow/models/taskinstance.py", line 3182, in _execute_task
    return _execute_task(self, context, task_orig)
           ^^^^^^^^^^^^^^^^^^^^^^^^^^^^^^^^^^^^^^^
  File "/home/airflow/.local/lib/python3.12/site-packages/airflow/models/taskinstance.py", line 767, in _execute_task
    result = _execute_callable(context=context, **execute_callable_kwargs)
             ^^^^^^^^^^^^^^^^^^^^^^^^^^^^^^^^^^^^^^^^^^^^^^^^^^^^^^^^^^^^^
  File "/home/airflow/.local/lib/python3.12/site-packages/airflow/models/taskinstance.py", line 733, in _execute_callable
    return ExecutionCallableRunner(
           ^^^^^^^^^^^^^^^^^^^^^^^^
  File "/home/airflow/.local/lib/python3.12/site-packages/airflow/utils/operator_helpers.py", line 252, in run
    return self.func(*args, **kwargs)
           ^^^^^^^^^^^^^^^^^^^^^^^^^^
  File "/home/airflow/.local/lib/python3.12/site-packages/airflow/models/baseoperator.py", line 406, in wrapper
    return func(self, *args, **kwargs)
           ^^^^^^^^^^^^^^^^^^^^^^^^^^^
  File "/home/airflow/.local/lib/python3.12/site-packages/airflow/operators/bash.py", line 249, in execute
    raise AirflowException(
airflow.exceptions.AirflowException: Bash command failed. The command returned a non-zero exit code 1.
[2025-10-30T15:10:43.499+0000] {local_task_job_runner.py:266} INFO - Task exited with return code 1
[2025-10-30T15:10:43.527+0000] {taskinstance.py:3900} INFO - 0 downstream tasks scheduled from follow-on schedule check
[2025-10-30T15:10:43.531+0000] {local_task_job_runner.py:245} INFO - ::endgroup::
